Workbook

Sheet Inputs
A1: PISTON & CONNECTING ROD DESIGN INPUTS
A4: Symbol | B4: Description | C4: Value | D4: Unit
A5: ENGINE GEOMETRY
A6: P | B6: Rated power per cylinder | C6: 6.23 | D6: kW
A7: N | B7: Engine speed | C7: 7500 | D7: rpm
A8: D | B8: Bore (cylinder diameter) | C8: 51 | D8: mm
A9: L | B9: Stroke | C9: 48.8 | D9: mm
A10: x | B10: 2 = four-stroke / 1 = two-stroke | C10: 2
A11: p | B11: Max gas pressure (design) | C11: 4.5 | D11: N/mm²
A12: r | B12: Crank radius (= L/2) | C12: =C9/2 -> 24.4 | D12: mm
A13: l | B13: Connecting rod length | C13: 97.9 | D13: mm
A14: omega | B14: Crank angular speed (= 2πN/60) | C14: =2*3.1416*C7/60 -> 785.4 | D14: rad/s
A16: PISTON MATERIAL-AL GHS 1300 Aluminum alloy
A17: σu_p | B17: Ultimate tensile strength piston | C17: 1300 | D17: N/mm²
A18: σy_p | B18: Yield (0.2 % proof) strength piston | C18: 1220 | D18: N/mm²
A19: σt_p | B19: Permissible bending stress (= σy/FOS) | C19: =C17/C30 -> 577.77778 | D19: N/mm²
A20: nu_p | B20: Poisson's ratio piston material | C20: 0.3
A21: k_p | B21: Thermal conductivity piston | C21: 120 | D21: W/m·K
A22: Tc | B22: Crown-centre temperature (service) | C22: 330 | D22: °C
A23: Te | B23: Crown-edge temperature (service) | C23: 250 | D23: °C
A24: pb_sk | B24: Permissible bearing pressure skirt | C24: 0.5 | D24: N/mm²
A25: pb_pin | B25: Permissible bearing pressure pin bush | C25: 25 | D25: N/mm²
A26: σb_pin | B26: Permissible bending stress pin | C26: 100 | D26: N/mm²
A27: k_pin | B27: Hollow ratio di/do (0 = solid pin) | C27: 0.6
A28: σt_rng | B28: Perm. bending stress ring material | C28: 110 | D28: N/mm²
A29: pw | B29: Mean ring-to-bore pressure | C29: 0.025 | D29: N/mm²
A30: FOS | B30: Factor of Safety | C30: 2.25
A31: HEAT FLOW (crown thickness cross-check)
A32: mf | B32: Fuel mass flow rate | C32: 0.00089 | D32: kg/s
A33: HCV | B33: Higher calorific value of fuel | C33: 44000 | D33: kJ/kg
A34: C | B34: Heat fraction through piston crown | C34: 0.05
A36: CONNECTING ROD MATERIAL-AL GHS 1300 Aluminum alloy
A37: σc_r | B37: Compressive yield stress rod | C37: 280 | D37: N/mm²
A38: σy_r | B38: Tensile yield strength rod | C38: 380 | D38: N/mm²
A39: σu_r | B39: Ultimate tensile strength rod | C39: 650 | D39: N/mm²
A40: a | B40: Rankine's constant | C40: 0.000133
A41: σe_r | B41: Endurance limit (rotating-beam test) | C41: 275 | D41: N/mm²
A42: Ka | B42: Surface finish factor (Marin) | C42: 0.8
A43: Kb | B43: Size factor (Marin) | C43: 0.85
A44: Kc | B44: Load-type factor (Marin) | C44: 1
...

Sheet Piston
A1: PISTON DESIGN
A4: Symbol | B4: Description | C4: Result | D4: Unit
A6: 1. GAS FORCE
A7: A | B7: Piston crown area | C7: =PI()/4*(Inputs!C8)^2 -> 2042.8206 | D7: mm²
A8: Fg | B8: Max gas force on piston | C8: =Inputs!C11*Piston!C7 -> 9192.6928 | D8: N
A10: 2. PISTON HEAD THICKNESS
A11: tH_str | B11: Head thickness - strength (Grashoff) | C11: =Inputs!C8*SQRT(3*Inputs!C11/(16*Inputs!C19)) -> 1.9489318 | D11: mm
A12: H | B12: Heat conducted through crown | C12: =Inputs!C34*Inputs!C33*1000*Inputs!C32 -> 1958 | D12: W
A13: tH_ht | B13: Head thickness - heat-dissipation | C13: =Piston!C12/(12.56*Inputs!C21*(Inputs!C22-Inputs!C23)) -> 0.016238721 | D13: mm
A14: tH | B14: DESIGN head thickness | C14: =MAX(Piston!C11,Piston!C13) -> 1.9489318 | D14: mm
A16: 3. COMPRESSION RINGS
A17: t2 | B17: Ring radial thickness | C17: =Inputs!C8*SQRT(3*Inputs!C29/Inputs!C28) -> 1.3316941 | D17: mm
A18: t3_min | B18: Ring axial width (min) | C18: =0.7*Piston!C17 -> 0.93218585 | D18: mm
A19: t3_max | B19: Ring axial width (max) | C19: =Piston!C17 -> 1.3316941 | D19: mm
A21: 4. BARREL, SKIRT & SKIRT LENGTH
A22: t_bar | B22: Barrel thickness | C22: =0.03*Inputs!C8+(Piston!C17+0.3)+4.5 -> 7.6616941 | D22: mm
A23: t_sk | B23: Skirt thickness | C23: =0.3*Piston!C22 -> 2.2985082 | D23: mm
A24: phi | B24: Crank obliquity angle | C24: =DEGREES(ASIN(Inputs!C12/Inputs!C13)) -> 14.432184 | D24: °
A25: Fn | B25: Side thrust on skirt | C25: =Inputs!C11*0.1*3.1416*(Inputs!C8^2)/4 -> 919.27143 | D25: N
A26: l_sk | B26: Skirt length | C26: =Piston!C25/(Inputs!C8*Inputs!C24) -> 36.04986 | D26: mm
A28: 5. GUDGEON PIN
A29: l_pin | B29: Pin bearing length (≈ 0.45D) | C29: =0.45*Inputs!C8 -> 22.95 | D29: mm
A30: do_brg | B30: Pin dia. - bearing pressure | C30: =Piston!C8/(Piston!C29*Inputs!C25) -> 16.022123 | D30: mm
A31: Mmax | B31: Max bending moment on pin | C31: =Piston!C8*Piston!C29/8 -> 26371.537 | D31: N·mm
A32: do_bnd | B32: Pin dia. - bending stress | C32: =(32*Piston!C31/(PI()*Inputs!C26*(1-Inputs!C27^4)))^(1/3) -> 14.559246 | D32: mm
A33: do | B33: DESIGN gudgeon pin diameter | C33: =MAX(Piston!C30,Piston!C32) -> 16.022123 | D33: mm
A35: 6. VON MISES STRESS - PISTON HEAD
A37: σr | B37: Radial bending stress at crown edge (max tensile face) | C37: =3*Inputs!C11*Inputs!C8^2/(16*Piston!C14^2) -> 577.77778 | D37: N/mm²
A38: σθ | B38: Hoop (circumferential) stress at same point | C38: =Inputs!C20*Piston!C37 -> 173.33333 | D38: N/mm²
A39: τ | B39: Shear stress in head plane | C39: 0 | D39: N/mm²
A40: σ_vm_p | B40: Von Mises equivalent stress - piston head | C40: =SQRT(Piston!C37^2+Piston!C38^2-Piston!C37*Piston!C38) -> 513.54012 | D40: N/mm²
A41: FOS_vm_y | B41: FOS against yield (Von Mises) | C41: =Inputs!C18/Piston!C40 -> 2.3756664 | D41: -
A42: FOS_vm_u | B42: FOS against fracture (Von Mises) | C42: =Inputs!C17/Piston!C40 -> 2.5314478 | D42: -

Sheet Connecting Rod
A1: CONNECTING ROD DESIGN
A4: Symbol | B4: Description | C4: Result | D4: Unit
A6: 1. I-SECTION PROPORTIONS (flange = 4t, depth = 5t, all walls = t)
A7: t | B7: Trial I-section web thickness | C7: 20 | D7: mm
A8: A | B8: Cross-section area | C8: =11*'Connecting Rod'!C7^2 -> 4400 | D8: mm²
A9: Ixx | B9: Second moment - swing plane (x-x) | C9: =419*'Connecting Rod'!C7^4/12 -> 5586666.7 | D9: mm⁴
A10: Iyy | B10: Second moment - perpendicular plane (y-y) | C10: ='Connecting Rod'!C9/3.2 -> 1745833.3 | D10: mm⁴
A11: kxx | B11: Radius of gyration - swing plane | C11: =SQRT('Connecting Rod'!C9/'Connecting Rod'!C8) -> 35.632807 | D11: mm
A12: kyy | B12: Radius of gyration - perpendicular plane | C12: =SQRT('Connecting Rod'!C10/'Connecting Rod'!C8) -> 19.919345 | D12: mm
A13: Zxx | B13: Section modulus about x-x axis | C13: ='Connecting Rod'!C9/(5*'Connecting Rod'!C7/2) -> 111733.33 | D13: mm³
A15: 2. DIRECT COMPRESSIVE STRESS (short column behaviour)
A16: σc_dir | B16: Direct compressive stress | C16: =Piston!C8/'Connecting Rod'!C8 -> 2.0892484 | D16: N/mm²
A18: 3. BENDING STRESS (whipping due to inertia)
A19: wi | B19: Distributed inertia load per unit length | C19: =(Inputs!C47/Inputs!C13)*Inputs!C14^2*Inputs!C12 -> 76870.363 | D19: N/mm
A20: M_wh | B20: Max whipping bending moment | C20: ='Connecting Rod'!C19*Inputs!C13^2/(12*SQRT(3)) -> 35447241 | D20: N·mm
A21: σ_bnd | B21: Whipping bending stress | C21: ='Connecting Rod'!C20/'Connecting Rod'!C13 -> 317.24858 | D21: N/mm²
A24: 4. VON MISES STRESS - CONNECTING ROD (compression + bending combined)
A25: σ_tot | B25: Combined stress at extreme fibre | C25: ='Connecting Rod'!C16+'Connecting Rod'!C21 -> 319.33783 | D25: N/mm²
A26: σ_vm_r | B26: Von Mises stress - rod | C26: ='Connecting Rod'!C25 -> 319.33783 | D26: N/mm²
A27: FOS_vm_ry | B27: FOS against yield (Von Mises) | C27: =Inputs!C38/'Connecting Rod'!C26 -> 1.1899624 | D27: -
A28: FOS_vm_ru | B28: FOS against fracture (Von Mises) | C28: =Inputs!C39/'Connecting Rod'!C26 -> 2.0354619 | D28: -
A30: 5. FATIGUE ANALYSIS - CONNECTING ROD (cyclic gas + inertia load)
A32: σe_prime | B32: Corrected endurance limit σe' | C32: =Inputs!C41*Inputs!C42*Inputs!C43*Inputs!C44*Inputs!C45*Inputs!C46 -> 151.47 | D32: N/mm²
A33: σ_max_f | B33: Max stress in fatigue cycle (= direct + bending) | C33: ='Connecting Rod'!C25 -> 319.33783 | D33: N/mm²
A34: σ_min_f | B34: Min stress in fatigue cycle (rod at BDC, gas ≈ 0) | C34: 0 | D34: N/mm²
A35: σm | B35: Mean stress | C35: =('Connecting Rod'!C33+'Connecting Rod'!C34)/2 -> 159.66891 | D35: N/mm²
A36: σa | B36: Stress amplitude | C36: =ABS('Connecting Rod'!C33-'Connecting Rod'!C34)/2 -> 159.66891 | D36: N/mm²
A37: FOS_Sod | B37: FOS (Soderberg) | C37: =1/('Connecting Rod'!C35/Inputs!C38+'Connecting Rod'!C36/'Connecting Rod'!C32) -> 0.67828325 | D37: -
A38: FOS_Gdm | B38: FOS (Goodman) | C38: =1/('Connecting Rod'!C35/Inputs!C39+'Connecting Rod'!C36/'Connecting Rod'!C32) -> 0.76936485 | D38: -
A40: 7. PIN BORE SIZES
A41: do_sm | B41: Small-end bore diameter (= gudgeon pin OD) | C41: =Piston!C33 -> 16.022123 | D41: mm
A42: l_sm | B42: Small-end bearing length | C42: =Piston!C8/(Piston!C33*12) -> 47.8125 | D42: mm
A43: l_big | B43: Big-end bearing length (≈ 1.15×do) | C43: =1.15*Piston!C33 -> 18.425441 | D43: mm
